Workbook

Sheet Stories
A1: ID | B1: Area | C1: Feature | D1: User story | E1: Expected behaviour (from code) | F1: Code refs | G1: How to test | H1: Status | I1: Test result | J1: Error notes | K1: Fix (commit / note) | L1: Retest result | M1: Last updated
A2: UI-01 | B2: UI: Dashboard | C2: Root redirect | D2: As an operator, I want / to take me to the dashboard so that the app has a single landing page. | E2: GET / returns 302 Location /dashboard (url_for('dashboard')). GET /dashboard returns 200 HTML titled 'DockSentinel — Overview'. | F2: app/web/routes.py:32-34, app/web/routes.py:37-69, app/templates/dashboard.html:2 | G2: curl -i http://127.0.0.1:5001/ → expect 302 + Location: /dashboard; curl -s http://127.0.0.1:5001/dashboard | grep 'Overview'. | H2: Pass | I2: GET / -> 302 Location /dashboard; GET /dashboard 200 with <title>DockSentinel — Overview</title>. | M2: 2026-08-15
A3: UI-02 | B3: UI: Dashboard | C3: Primary nav with active link | D3: As an operator, I want a header nav on every page so that I can move between Overview/Events/Issues/Reports/Exclusions/Prompts/Settings. | E3: Sidebar nav renders 7 links grouped Monitor/Configure; the link whose path prefix matches gets nav__link--active + aria-current='page'; brand link -> /dashboard. | F3: app/templates/base.html:20-36 | G3: curl -s http://127.0.0.1:5001/insights | grep -c 'nav__link--active' → 1 and it wraps 'Events'; repeat for /settings, /prompts. | H3: Pass | I3: base.html renders 7 nav links (Monitor: Overview/Events/Issues/Reports; Configure: Settings/Exclusions/Prompts) in a sidebar. Exactly one nav__link--active + aria-current=page per page: /insights->Events, /settings->Settings, /prompts->Prompts, /dashboard->Overview. Both brand links href=/dashboard. | M3: 2026-08-15
A4: UI-03 | B4: UI: Dashboard | C4: Sentinel running/stopped badge | D4: As an operator, I want to see at a glance whether the sentinel is enabled so that I know if containers are watched. | E4: Hero card title 'Sentinel is running|stopped|degraded' (hero--running/--stopped/--degraded, pulse--live when enabled) with a 'Runtime' fact showing state.runtime_status in mono text. | F4: app/templates/dashboard.html:9-16, app/web/routes.py:40 | G4: GET /dashboard, grep for 'badge--ok">running' or 'badge--neutral">stopped'; POST /sentinel/toggle enabled=false then re-GET and confirm 'stopped'. | H4: Pass | I4: Badge replaced by status hero: 'Sentinel is stopped' (hero--stopped) when disabled; 'Sentinel is running' (hero--running, pulse--live) when enabled; 'Sentinel is degraded' when enabled and llm_failure_count>0 or last_error. Runtime fact shows state.runtime_status in mono. Verified via /sentinel/toggle. | M4: 2026-08-15
A5: UI-04 | B5: UI: Dashboard | C5: Stopped-sentinel warning banner with Start button | D5: As an operator, I want a warning banner when the sentinel is stopped so that I can start it in one click. | E5: When not enabled the hero card reads 'Sentinel is stopped.' with a Settings link and a POST /sentinel/toggle (enabled=true) 'Start sentinel' button; when enabled it shows Stop instead. | F5: app/templates/dashboard.html:25-36, app/web/routes.py:293-298 | G5: curl -X POST -d enabled=false http://127.0.0.1:5001/sentinel/toggle; GET /dashboard → banner present. Then POST enabled=true → banner gone. | H5: Pass | I5: When stopped, hero--stopped shows 'Sentinel is stopped' + 'No containers are being watched…', a form POST /sentinel/toggle enabled=true 'Start sentinel' and a Settings link (/settings). When enabled the Start form is gone (Stop shown instead). | M5: 2026-08-15
A6: UI-05 | B6: UI: Dashboard | C6: Start / Stop sentinel buttons | D6: As an operator, I want Start and Stop buttons so that I can toggle the sentinel from the Overview. | E6: One form POST /sentinel/toggle is rendered: hidden enabled=false 'Stop sentinel' when enabled, else enabled=true 'Start sentinel' (btn--primary). Non-'true' or missing value => disabled. Always 302 /dashboard. | F6: app/templates/dashboard.html:42-51, app/web/routes.py:293-298 | G6: curl -i -X POST -d enabled=true http://127.0.0.1:5001/sentinel/toggle → 302 /dashboard; GET /dashboard shows Start button with 'disabled'. Attach may need docker; toggle itself works without. | H6: Pass | I6: POST enabled=true -> 302 /dashboard, page then shows only 'Stop sentinel' (enabled=false form); enabled=false -> only 'Start sentinel'. enabled=yes or missing -> treated as false (stopped). Only one form is rendered at a time instead of a disabled pair. | M6: 2026-08-15
A7: UI-06 | B7: UI: Dashboard | C7: Sentinel stat tiles | D7: As an operator, I want Active containers, LLM failures and Runtime stats so that I can judge health. | E7: Hero facts: Runtime = runtime_status; Attached = len(active_container_ids()) containers; LLM failures = llm_failure_count (text-warning if >0); Since = started_at or '—'. | F7: app/templates/dashboard.html:54-70, app/web/routes.py:66 | G7: GET /dashboard and inspect the three .stat blocks; without docker Active is 0 and 'not started' shown until sentinel started. | H7: Pass | I7: Hero facts: Runtime=state.runtime_status (mono), Attached='N container(s)' from active_container_ids(), LLM failures (text-warning when >0), Since=started_at or '—'. Without docker: 0 containers, 0 failures, Since '—' when stopped, timestamp when started. | M7: 2026-08-15
A8: UI-07 | B8: UI: Dashboard | C8: Analyze-now container picker (JS) | D8: As an operator, I want to pick a running container from a dropdown or type one so that I can trigger an immediate analysis. | E8: Select lists sorted running docker container names + 'Other…'; if docker unavailable only 'Enter container manually…' (value __other__) and the text input is visible. JS: choosing __other__ reveals/focuses input; on submit, a picked name is copied into input name=container; empty selection or empty custom blocks submit. | F8: app/templates/dashboard.html:72-94, app/web/routes.py:72-84, app/static/app.js:102-133 | G8: Open /dashboard in browser (no docker → manual input shown). Click 'Analyze now' with empty input → no navigation. Docker daemon needed to see real names in the select. | H8: Pass | I8: No docker: select[data-analyze-select] has single option __other__ 'Enter container manually…' and input[name=container][data-analyze-custom] is not hidden. app.js wireAnalyzeForm finds data-analyze-form/select/custom; blocks submit when custom empty; copies picked name into input. Real names need docker (not testable). | M8: 2026-08-15
A9: UI-08 | B9: UI: Dashboard | C9: Analyze-now submission and error banner | D9: As an operator, I want analyze failures shown on the dashboard so that I know why a run did not happen. | E9: Dashboard renders a banner--critical role=alert 'Analyze failed.' with the analyze_error text when the query param is present. | F9: app/web/routes.py:301-311, app/templates/dashboard.html:19-23 | G9: curl -i -X POST -d container= http://127.0.0.1:5001/sentinel/analyze → Location contains analyze_error=no+container+selected; curl -i -X POST -d container=nosuch … → 302 with error text (docker not available error). GET that Location and grep 'Analyze failed'. | H9: Pass | I9: POST container= -> 302 /dashboard?analyze_error=no+container+selected; container=nosuch -> 302 with analyze_error=Error while fetching server API version… ; GET with analyze_error renders banner--critical 'Analyze failed.' + text; absent otherwise. | M9: 2026-08-15
A10: UI-09 | B10: UI: Dashboard | C10: Today counts card | D10: As an operator, I want today's critical/warning/noise/skipped/error counts so that I can see the day's signal. | E10: Today stat tiles Critical/Warning/Noise (LLM)/Skipped (prefilter) computed as before; 'Errors' tile only rendered when counts.errors>0. | F10: app/web/routes.py:41-55, app/templates/dashboard.html:98-113 | G10: GET /dashboard, read dl.kv values; verify 'Errors' dt absent when no llm/parse errors today. Seed events via DB or API to check math. | H10: Pass | I10: Seeded 7 events today: Critical 1, Warning 1, Noise (LLM) 1, Skipped (prefilter) 2 (skipped+dedup_skipped), Errors 1 (llm_error), container_event ignored. Temporarily changing the llm_error row to excluded gave Skipped 3 and the Errors tile disappeared. | M10: 2026-08-15
A11: UI-10 | B11: UI: Dashboard | C11: Generate nightly report button (dashboard) | D11: As an operator, I want to trigger a report from the Overview so that I don't need to open Reports. | E11: Form POST /reports/generate calls briefing.generate_report() and 302-redirects to /reports (not back to dashboard). | F11: app/templates/dashboard.html:114-116, app/web/routes.py:219-222 | G11: curl -i -X POST http://127.0.0.1:5001/reports/generate → 302 Location /reports; GET /reports shows a new archive entry (status generated or llm error). | H11: Pass | I11: POST /reports/generate -> 302 Location /reports; new report #2 (llm_error, no LLM reachable) appeared first in archive and as Latest report on dashboard. Removed afterwards. | M11: 2026-08-15
A12: UI-11 | B12: UI: Dashboard | C12: Latest report link card | D12: As an operator, I want a link to the most recent report so that I can open it quickly. | E12: 'Latest report' card always renders; with a report it links /reports?id=<id> showing '#<id>', created_at and a status badge; with none it shows 'No nightly report yet' + Generate button. | F12: app/templates/dashboard.html:119-128, app/web/routes.py:58 | G12: On fresh DB GET /dashboard has no 'Latest report'; after POST /reports/generate it appears with href /reports?id=1. | H12: Pass | I12: With report present: 'Latest report' card has row-link href=/reports?id=1, '#1', created_at and status badge (generated/llm error). With reports table temporarily empty: card shows 'No nightly report yet' + 'Generate nightly report' form instead of being omitted. | M12: 2026-08-15
A13: UI-12 | B13: UI: Dashboard | C13: Recent events table | D13: As an operator, I want the 10 most recent events with severity/status/summary so that I can spot recent activity. | E13: Table of event_repo.get_recent(limit=10): time, container, badge critical/warning/else noise (classification or 'noise'), mono status, summary or '—'. Empty → 'No events yet' empty state. 'View all →' links to /insights. | F13: app/templates/dashboard.html:132-179, app/web/routes.py:57 | G13: GET /dashboard: on empty DB grep 'No events yet'; with events confirm ≤10 rows and 'View all' href=/insights. | H13: Pass | I13: Recent events table renders 7 rows (<=10) with time, container link, badge critical/warning/noise, mono status, summary/—; 'View all' href=/insights. With events temporarily removed: 'No events yet' empty state (+ Start sentinel CTA when stopped). | M13: 2026-08-15
... A53: UI-52 | B53: UI: Settings | C53: Sticky section nav anchors | D53: As an operator I can jump between settings sections. | E53: nav[data-section-nav] links #llm,#budgets,#alerts,#limits,#scheduler each match a section id on the page; app.js wireSectionNav highlights via IntersectionObserver. | F53: app/templates/settings.html:29-35,39,89,113,151,182, app/static/app.js:338-359 | G53: curl -s /settings | grep -oE 'href="#[a-z]+"|section" id="[a-z]+"' and compare sets. | H53: Pass | I53: Anchors {#llm,#budgets,#alerts,#limits,#scheduler} exactly match section ids; #main skip link targets main#main. | M53: 2026-08-15
A54: UI-53 | B54: UI: Global | C54: Empty states have a CTA | D54: As a user every empty state offers a next action. | E54: Every data-empty state renders a link or button: dashboard events (Start sentinel), latest report (Generate), events (Clear filters / Go to Overview), reports (Generate now), issues (Show all / hint), exclusions (add form). | F54: app/templates/dashboard.html:170-180,254-260, app/templates/insights.html:126-137, app/templates/reports.html:37-46, app/templates/issues.html:47-56, app/templates/exclusions.html:53-61 | G54: Temporarily empty each table (backup/restore via sqlite3) and grep the empty state for <a class="btn"|<button. | H54: Pass (after fix) | I54: CTA present: dashboard events (Start sentinel when stopped), latest report (Generate nightly report), events (Clear filters / Go to Overview), reports (Generate now), issues filtered (Show all). Missing: exclusions 'No exclusions configured' (text only, no button/link) and issues unfiltered 'No issues' (Telegram hint, no link). | J54: Expected every empty state to have a CTA link/button; observed none in app/templates/exclusions.html:53-59 (empty state has only text; add form is above) and app/templates/issues.html:47-54 when no status filter (no link/button). Also dashboard 'No events yet' has no CTA when sentinel is enabled (dashboard.html:170-179). | K54: empty states now carry a CTA (Add a pattern / Browse events / Open events) | L54: CTA present in every empty state (verified issues?status=closed 'Show all'; exclusions template has 'Add a pattern') | M54: 2026-08-15
A55: UI-54 | B55: UI: Global | C55: Page titles | D55: As a user each page tab reads 'DockSentinel — <Page>'. | E55: Titles: /dashboard Overview, /insights Events, /issues Issues, /reports Reports, /settings Settings, /exclusions Exclusions, /prompts Prompts (7 pages; / redirects to dashboard). | F55: app/templates/*.html:2, app/templates/base.html:7 | G55: for p in dashboard insights issues reports settings exclusions prompts; do curl -s /$p | grep -o '<title>.*</title>'; done | H55: Pass | I55: All 7 pages return 'DockSentinel — Overview|Events|Issues|Reports|Settings|Exclusions|Prompts'; / is a 302 to /dashboard (8th route). Sidebar topbar__title matches active label. | M55: 2026-08-15
A56: UI-55 | B56: UI: Global | C56: No external network assets | D56: As a homelab user the UI works offline. | E56: No <link>/<script src> with http(s):// on any page; CSS/JS/favicon served from /static; icons are inline SVG symbols; no CDN fonts. | F56: app/templates/base.html:8-19, app/static/css/app.css | G56: for each page: curl -s | grep -E '<link|<script' | grep -E 'https?://' -> empty; grep -c '@import\|url(http' app/static/css/app.css -> 0. | H56: Pass | I56: No http(s):// in any <link>/<script> on all 7 pages; only /static/css/app.css, /static/app.js, /static/favicon.svg. app.css has no @import/url(http…). Icons are inline <symbol> sprites. | M56: 2026-08-15
A57: UI-56 | B57: UI: Prompts | C57: Restore-default disabled state | D57: As an editor the Restore default button is disabled when the prompt is already default. | E57: button[name=action][value=reset] has 'disabled' when selected_prompt.is_default; enabled after saving custom content; disabled again after reset. | F57: app/templates/prompt_studio.html:39, app/web/routes.py:231-247 | G57: curl -s /prompts | grep 'value="reset" disabled'; POST action=save content=x key=SENTINEL_ANALYSIS; GET -> no disabled; POST action=reset -> disabled again. | H57: Pass | I57: Default prompt: 'value="reset" disabled'; after saving 'new text' the attribute is absent (badge customised); after reset it is disabled again (badge default). Prompt restored to version 1. | M57: 2026-08-15
A58: API-01 | B58: API: Health | C58: Health probe | D58: As an operator I want GET /api/health so Docker HEALTHCHECK can verify the app is up. | E58: 200 JSON {status:'ok', runtime:{enabled,runtime_status,started_at,last_error,llm_failure_count,llm_last_failure_at,updated_at}}. Always open even when basic auth is enabled. | F58: app/api/health.py:12-15; app/schemas/health.py:8-10; app/security.py:22,66-67 | G58: curl -s -i http://127.0.0.1:5001/api/health | head -20 # expect 200 and status:'ok' with runtime object | H58: Pass | I58: GET /api/health -> 200 application/json {status:'ok', runtime:{enabled,runtime_status,started_at,last_error,llm_failure_count,llm_last_failure_at,updated_at}}; all 7 runtime keys present. | M58: 2026-08-15
A59: API-02 | B59: API: Security | C59: Origin guard - cross-site POST rejected | D59: As an operator I want state-changing requests with a foreign Origin header rejected to prevent CSRF. | E59: Any non-GET/HEAD/OPTIONS request whose Origin netloc != request Host (or X-Forwarded-Host) → 403 with description 'cross-site request rejected' (Flask default 403 body). | F59: app/security.py:21,50-59 | G59: curl -s -o /dev/null -w '%{http_code}' -X POST -H 'Origin: http://evil.example' http://127.0.0.1:5001/api/sentinel/toggle -H 'Content-Type: application/json' -d '{}' # expect 403 | H59: Pass | I59: POST /api/sentinel/toggle with Origin: http://evil.example -> 403, Flask default HTML body containing 'cross-site request rejected'. | M59: 2026-08-15
A60: API-03 | B60: API: Security | C60: Origin guard - Origin: null rejected | D60: As an operator I want Origin: null (sandboxed/opaque origins) treated as cross-site. | E60: POST with header Origin: null → 403. | F60: app/security.py:56-58 | G60: curl -s -o /dev/null -w '%{http_code}' -X POST -H 'Origin: null' http://127.0.0.1:5001/api/sentinel/toggle -H 'Content-Type: application/json' -d '{}' # expect 403 | H60: Pass | I60: POST with Origin: null -> 403. | M60: 2026-08-15
A61: API-04 | B61: API: Security | C61: Origin guard - same-origin allowed | D61: As the web UI I want same-host Origin accepted so browser fetches work. | E61: POST with Origin: http://127.0.0.1:5001 passes the guard (proceeds to handler, e.g. 200). | F61: app/security.py:25-27,37,56-59 | G61: curl -s -o /dev/null -w '%{http_code}' -X POST -H 'Origin: http://127.0.0.1:5001' http://127.0.0.1:5001/api/sentinel/toggle -H 'Content-Type: application/json' -d '{"enabled":false}' # expect 200 | H61: Pass | I61: POST toggle with Origin: http://127.0.0.1:5001 -> 200 {state:{enabled:false,...}} (guard passed, handler ran). | M61: 2026-08-15
A62: API-05 | B62: API: Security | C62: Origin guard - Referer fallback | D62: As an operator I want cross-site Referer (when no Origin) rejected too. | E62: POST without Origin but Referer pointing at another host → 403; Referer with same host → allowed. | F62: app/security.py:54,60-61 | G62: curl -s -o /dev/null -w '%{http_code}' -X POST -H 'Referer: http://evil.example/page' http://127.0.0.1:5001/api/sentinel/toggle -H 'Content-Type: application/json' -d '{}' # expect 403 | H62: Pass | I62: No Origin + Referer http://evil.example/page -> 403; Referer http://127.0.0.1:5001/page -> 200. | M62: 2026-08-15
A63: API-06 | B63: API: Security | C63: Origin guard - X-Forwarded-Host honoured | D63: As an operator behind a reverse proxy I want Origin matching X-Forwarded-Host accepted. | E63: POST with Origin: https://public.example and X-Forwarded-Host: public.example → not rejected by guard. | F63: app/security.py:30-43 | G63: curl -s -o /dev/null -w '%{http_code}' -X POST -H 'Origin: https://public.example' -H 'X-Forwarded-Host: public.example' http://127.0.0.1:5001/api/sentinel/toggle -H 'Content-Type: application/json' -d '{"enabled":false}' # expect 200 | H63: Pass | I63: Origin https://public.example + X-Forwarded-Host public.example -> 200 {state:...}. | M63: 2026-08-15
A64: API-07 | B64: API: Security | C64: Origin guard - safe methods bypass | D64: As any client I want GET requests unaffected by the origin check. | E64: GET with foreign Origin still returns 200 (guard only inspects non-safe methods). | F64: app/security.py:21,51-52 | G64: curl -s -o /dev/null -w '%{http_code}' -H 'Origin: http://evil.example' http://127.0.0.1:5001/api/settings # expect 200 | H64: Pass | I64: GET /api/settings with Origin: http://evil.example -> 200. | M64: 2026-08-15
A65: API-08 | B65: API: Security | C65: Basic auth 401 when enabled | D65: As an operator who set BASIC_AUTH_USER/BASIC_AUTH_PASSWORD I want unauthenticated requests refused. | E65: When both env vars set: any path except /api/health without valid Basic creds → 401 body 'authentication required', header WWW-Authenticate: Basic realm="DockSentinel". Correct creds → normal response. Not enabled → no auth required. | F65: app/security.py:64-82,90-96 | G65: Requires server started with BASIC_AUTH_USER=u BASIC_AUTH_PASSWORD=p. curl -s -i http://127.0.0.1:5001/api/settings | head -3 # 401 + WWW-Authenticate; then curl -u u:p ... # 200. Fallback if not enabled: expect 200 without creds. | H65: Pass | I65: Second instance on :5002 with BASIC_AUTH_USER=u/PASSWORD=p: GET /api/settings no creds -> 401 body 'authentication required' + WWW-Authenticate: Basic realm="DockSentinel"; -u u:p -> 200; -u u:wrong -> 401; GET / and POST toggle -> 401. Main :5001 (not enabled) -> 200 without creds. | M65: 2026-08-15
A66: API-09 | B66: API: Security | C66: Basic auth exempts /api/health | D66: As Docker HEALTHCHECK I want /api/health reachable without credentials. | E66: With basic auth enabled, GET /api/health → 200 without Authorization header. | F66: app/security.py:22,66-67 | G66: With BASIC_AUTH_* set: curl -s -o /dev/null -w '%{http_code}' http://127.0.0.1:5001/api/health # expect 200 | H66: Pass | I66: On :5002 with basic auth enabled, GET /api/health without Authorization -> 200 {status:'ok',runtime:{...}}. | M66: 2026-08-15
... A113: API-56 | B113: API: General | C113: Unknown route / wrong method | D113: As a client I want standard 404/405 for unmapped paths and methods. | E113: GET /api/nope → 404 (Flask default); DELETE /api/settings → 405. | F113: app/__init__.py:31-48 | G113: curl -s -o /dev/null -w '%{http_code}' http://127.0.0.1:5001/api/nope # 404; curl -s -o /dev/null -w '%{http_code}' -X DELETE http://127.0.0.1:5001/api/settings # 405 | H113: Pass | I113: GET /api/nope -> 404; DELETE /api/settings -> 405. | M113: 2026-08-15
A114: API-57 | B114: API: Settings | C114: Settings response includes updated_at | D114: As an operator I want to see when settings last changed. | E114: GET/PUT /api/settings response contains updated_at (ISO datetime or null); PUT bumps it after save. | F114: app/schemas/settings.py:71; app/api/settings.py:39-42 | G114: curl -s http://127.0.0.1:5001/api/settings | grep -o '"updated_at": *"[^"]*"' | H114: Pass (after fix) | I114: GET/PUT /api/settings include updated_at and PUT bumps it (20:17:53 -> 20:18:05 after later PUT). But value is RFC 1123 HTTP-date 'Sat, 15 Aug 2026 20:18:05 GMT', not ISO 8601. | J114: Expected ISO datetime string; observed 'Sat, 15 Aug 2026 20:18:05 GMT'. Cause: SettingsSchema.model_dump() (app/schemas/settings.py:74) yields datetime, and Flask default JSON provider (no custom provider in app/__init__.py) serializes datetimes as HTTP-date. Same format on all other endpoints. Minor severity. | K114: __init__.py: ISOJSONProvider — datetimes serialised ISO-8601 | L114: updated_at now ISO-8601 (2026-08-15T20:36:56) | M114: 2026-08-15
A115: API-58 | B115: API: Security | C115: Session cookie hardening | D115: As an operator I want cookies SameSite=Lax and HttpOnly by default. | E115: App config SESSION_COOKIE_SAMESITE='Lax', SESSION_COOKIE_HTTPONLY=True set at install_security; BASIC_AUTH_ENABLED flag reflects env. | F115: app/security.py:85-96 | G115: Config-level; verify via python: from app import create_app; a=create_app(); print(a.config['SESSION_COOKIE_SAMESITE'], a.config['BASIC_AUTH_ENABLED']) | H115: Pass (after fix) | I115: create_app() config: SESSION_COOKIE_SAMESITE=None, SESSION_COOKIE_HTTPONLY=True, BASIC_AUTH_ENABLED=True with env vars set / False without. | J115: Expected SESSION_COOKIE_SAMESITE='Lax'; observed None. app/security.py:86 uses app.config.setdefault('SESSION_COOKIE_SAMESITE','Lax') but Flask's default config already defines that key as None, so setdefault is a no-op. HTTPONLY and BASIC_AUTH_ENABLED are correct. | K115: security.py: explicit set (Flask predefines key as None so setdefault was a no-op) | L115: SESSION_COOKIE_SAMESITE == 'Lax' | M115: 2026-08-15
A116: PIPE-01 | B116: Pipeline: Watcher | C116: Watcher start is idempotent | D116: As an operator, restarting the watcher must not leak old threads. | E116: start() calls stop() first if an event thread, reconcile thread or client already exists; then creates fresh _stop_event/_reconcile_now Events, docker.from_env(), starts daemon threads 'docker-events' and 'docker-reconcile', and runs reconcile() once synchronously. | F116: app/services/docker_watcher.py:46-67 | G116: tests/test_docker_watcher.py::test_stop_joins_threads_and_start_uses_fresh_events (patches docker.from_env with a fake client). | H116: Pass | I116: start() twice: stop() invoked once on restart, fresh Events, from_env twice, daemon threads named docker-events/docker-reconcile, reconcile ran once synchronously | M116: 2026-08-15
A117: PIPE-02 | B117: Pipeline: Watcher | C117: Watcher stop tears down workers | D117: As an operator, stopping the watcher must stop all per-container tail threads and close the docker client. | E117: stop() sets stop_event and reconcile_now, pops every worker, sets each worker stop_flag and joins with timeout=1, closes client (errors swallowed), joins event/reconcile threads with timeout=2 (skipping current thread), and nulls both thread refs. | F117: app/services/docker_watcher.py:69-92 | G117: tests/test_docker_watcher.py::test_stop_joins_threads_and_start_uses_fresh_events; assert active_container_ids()==[] after stop(). | H117: Pass | I117: stop(): stop_event+reconcile_now set, workers popped+joined, client closed (error swallowed) & nulled, threads joined & nulled, active_container_ids()==[] | M117: 2026-08-15
A118: PIPE-03 | B118: Pipeline: Watcher | C118: Event stream attach/detach | D118: As an operator, containers that start are tailed automatically and stopped ones are detached quickly. | E118: _watch_events iterates client.events(decode=True); ignores non-'container' types and events without id; on status start/restart calls _attach_container; on die/destroy/stop calls _detach_container. Any exception ends the loop with an exception log and relies on reconcile. | F118: app/services/docker_watcher.py:101-125 | G118: tests/test_container_events.py::test_watcher_dispatches_container_events uses a fake client whose events() yields dicts; assert _attach/_detach called via monkeypatch. No docker daemon needed. | H118: Pass | I118: start/restart->attach, die/destroy/stop->detach, non-container & id-less ignored, stream exception swallowed | M118: 2026-08-15
A119: PIPE-04 | B119: Pipeline: Watcher | C119: Lifecycle event dispatch | D119: As an operator, die/oom/kill/restart/start/unhealthy events reach the sentinel so they can be recorded. | E119: _dispatch_container_event forwards only statuses in CONTAINER_EVENT_STATUSES {die,oom,kill,restart,start,'health_status: unhealthy'}; copies Actor.Attributes, coerces exitCode to int when possible; name falls back to id[:12]; callback exceptions are logged and never stop the stream; no callback configured -> no-op. | F119: app/services/docker_watcher.py:21,127-144 | G119: tests/test_container_events.py::test_watcher_dispatches_container_events, ::test_watcher_callback_exception_does_not_kill_event_stream, ::test_watcher_without_callback_ignores_events. | H119: Pass | I119: existing tests pass; extra: name fallback id[:12], exitCode int coercion + raw fallback, attrs copied, non-listed status ignored | M119: 2026-08-15
A120: PIPE-05 | B120: Pipeline: Watcher | C120: Periodic reconcile loop | D120: As an operator, if the event stream misses something, the watcher self-heals within a minute. | E120: _reconcile_loop waits up to reconcile_interval_seconds (coordinator passes 60) on reconcile_now; when woken it clears the event and calls reconcile(); exits when its bound stop_event is set. force_reconcile() sets reconcile_now. | F120: app/services/docker_watcher.py:98-99,146-161; app/services/coordinator.py:239 | G120: Construct DockerWatcher with reconcile_interval_seconds=0.05 and a fake client; call force_reconcile(); assert reconcile ran (patch reconcile with a counter). No daemon needed. | H120: Pass | I120: force_reconcile wakes loop, event cleared, periodic ticks (5 in ~0.3s @0.05s), exits on stop_event | M120: 2026-08-15
A121: PIPE-06 | B121: Pipeline: Watcher | C121: Reconcile computes desired vs active set | D121: As an operator, running non-excluded containers are attached and vanished ones are detached. | E121: reconcile() lists client.containers.list(), drops containers where is_excluded_callback(name) is True, attaches desired-active ids, detaches active-desired ids (detach with name None). No-op when client is None. | F121: app/services/docker_watcher.py:163-183 | G121: Fake client with containers.list() returning objects with id/name/status; patch _tail_container to a no-op; assert active_container_ids() matches desired set and exclusion callback filters names. | H121: Pass | I121: excluded names filtered, desired-active attached, active-desired detached (name None), no-op when client None | M121: 2026-08-15
A122: PIPE-07 | B122: Pipeline: Watcher | C122: Attach guards | D122: As an operator, a container is never tailed twice and excluded containers are never attached. | E122: _attach_container returns early if id already in _workers (checked before and after containers.get), if containers.get raises, or if is_excluded_callback(container.name). Otherwise registers (name, thread, stop_flag) and starts a daemon thread named 'log-tail-<name>'. | F122: app/services/docker_watcher.py:185-214 | G122: Fake client; call _attach_container twice for same id; assert one worker. Call with excluded name; assert no worker. | H122: Pass | I122: double attach -> one worker; excluded name -> none; containers.get error -> none; thread named log-tail-<name>, daemon | M122: 2026-08-15
A123: PIPE-08 | B123: Pipeline: Watcher | C123: Detach triggers final flush | D123: As an operator, when a container stops, buffered lines are flushed for analysis rather than lost. | E123: _detach_container pops worker, sets stop_flag, joins thread (timeout=1), then calls line_callback(container_id, container_name or stored name, '', True) (flush_only). Unknown id -> no-op. | F123: app/services/docker_watcher.py:216-226 | G123: Register a fake worker in watcher._workers, call _detach_container, assert callback received flush_only=True with '' line. | H123: Pass | I123: detach pops worker, sets stop_flag, joins, callback(id, name-or-stored, '', True); unknown id no-op | M123: 2026-08-15
A124: PIPE-09 | B124: Pipeline: Watcher | C124: Tail reconnects after stream drop | D124: As an operator, a quiet container whose log stream times out keeps being monitored. | E124: _tail_container loops while container.status in {running,restarting}; container.logs(stream=True,follow=True,stdout=True,stderr=True,since=<epoch>) is re-opened after an exception with backoff starting 1.0s doubling to max 30s; since/backoff reset on each payload; empty lines skipped; clean end of stream breaks the loop. | F124: app/services/docker_watcher.py:228-269 | G124: tests/test_docker_watcher.py::test_dropped_stream_reconnects_then_deregisters_when_container_exits. | H124: Pass | I124: backoff 1,2,4,8,16,30,30; logs(stream,follow,stdout,stderr,since); empty lines skipped; clean end breaks; not-running exits | M124: 2026-08-15
A125: PIPE-10 | B125: Pipeline: Watcher | C125: Line callback errors don't kill tail | D125: As an operator, a DB hiccup on one line must not stop monitoring the container. | E125: Exceptions raised by line_callback are logged ('log line handler failed...') and the loop continues with the next payload. | F125: app/services/docker_watcher.py:257-260 | G125: tests/test_docker_watcher.py::test_line_callback_exception_does_not_kill_stream. | H125: Pass | I125: tests/test_docker_watcher.py::test_line_callback_exception_does_not_kill_stream passes: callback raising on 'boom' is logged, 'one','two' still delivered, single logs() call (no reconnect). | M125: 2026-08-15
...

Sheet Summary
A1: Status | B1: Count
A2: Not tested | B2: =COUNTIF(Stories!$H$2:$H$248,A2)
A3: Pass | B3: =COUNTIF(Stories!$H$2:$H$248,A3)
A4: Fail | B4: =COUNTIF(Stories!$H$2:$H$248,A4)
A5: Fixed - retest | B5: =COUNTIF(Stories!$H$2:$H$248,A5)
A6: Pass (after fix) | B6: =COUNTIF(Stories!$H$2:$H$248,A6)
A7: Blocked (needs docker/LLM/Telegram) | B7: =COUNTIF(Stories!$H$2:$H$248,A7)
A8: Won't fix | B8: =COUNTIF(Stories!$H$2:$H$248,A8)
A9: Total stories | B9: =COUNTA(Stories!$A$2:$A$248)
A10: Pass rate (Pass + Pass after fix) | B10: =IFERROR((B3+B6)/B9,0)
A12: Per area
A13: Area | B13: Stories | C13: Pass | D13: Fail
A14: API: Errors | B14: =COUNTIF(Stories!$B$2:$B$248,A14) | C14: =COUNTIFS(Stories!$B$2:$B$248,A14,Stories!$H$2:$H$248,"Pass")+COUNTIFS(Stories!$B$2:$B$248,A14,Stories!$H$2:$H$248,"Pass (after fix)") | D14: =COUNTIFS(Stories!$B$2:$B$248,A14,Stories!$H$2:$H$248,"Fail")
A15: API: Exclusions | B15: =COUNTIF(Stories!$B$2:$B$248,A15) | C15: =COUNTIFS(Stories!$B$2:$B$248,A15,Stories!$H$2:$H$248,"Pass")+COUNTIFS(Stories!$B$2:$B$248,A15,Stories!$H$2:$H$248,"Pass (after fix)") | D15: =COUNTIFS(Stories!$B$2:$B$248,A15,Stories!$H$2:$H$248,"Fail")
A16: API: General | B16: =COUNTIF(Stories!$B$2:$B$248,A16) | C16: =COUNTIFS(Stories!$B$2:$B$248,A16,Stories!$H$2:$H$248,"Pass")+COUNTIFS(Stories!$B$2:$B$248,A16,Stories!$H$2:$H$248,"Pass (after fix)") | D16: =COUNTIFS(Stories!$B$2:$B$248,A16,Stories!$H$2:$H$248,"Fail")
A17: API: Health | B17: =COUNTIF(Stories!$B$2:$B$248,A17) | C17: =COUNTIFS(Stories!$B$2:$B$248,A17,Stories!$H$2:$H$248,"Pass")+COUNTIFS(Stories!$B$2:$B$248,A17,Stories!$H$2:$H$248,"Pass (after fix)") | D17: =COUNTIFS(Stories!$B$2:$B$248,A17,Stories!$H$2:$H$248,"Fail")
A18: API: Insights | B18: =COUNTIF(Stories!$B$2:$B$248,A18) | C18: =COUNTIFS(Stories!$B$2:$B$248,A18,Stories!$H$2:$H$248,"Pass")+COUNTIFS(Stories!$B$2:$B$248,A18,Stories!$H$2:$H$248,"Pass (after fix)") | D18: =COUNTIFS(Stories!$B$2:$B$248,A18,Stories!$H$2:$H$248,"Fail")
A19: API: Issues | B19: =COUNTIF(Stories!$B$2:$B$248,A19) | C19: =COUNTIFS(Stories!$B$2:$B$248,A19,Stories!$H$2:$H$248,"Pass")+COUNTIFS(Stories!$B$2:$B$248,A19,Stories!$H$2:$H$248,"Pass (after fix)") | D19: =COUNTIFS(Stories!$B$2:$B$248,A19,Stories!$H$2:$H$248,"Fail")
A20: API: Ollama | B20: =COUNTIF(Stories!$B$2:$B$248,A20) | C20: =COUNTIFS(Stories!$B$2:$B$248,A20,Stories!$H$2:$H$248,"Pass")+COUNTIFS(Stories!$B$2:$B$248,A20,Stories!$H$2:$H$248,"Pass (after fix)") | D20: =COUNTIFS(Stories!$B$2:$B$248,A20,Stories!$H$2:$H$248,"Fail")
A21: API: Prompts | B21: =COUNTIF(Stories!$B$2:$B$248,A21) | C21: =COUNTIFS(Stories!$B$2:$B$248,A21,Stories!$H$2:$H$248,"Pass")+COUNTIFS(Stories!$B$2:$B$248,A21,Stories!$H$2:$H$248,"Pass (after fix)") | D21: =COUNTIFS(Stories!$B$2:$B$248,A21,Stories!$H$2:$H$248,"Fail")
A22: API: Reports | B22: =COUNTIF(Stories!$B$2:$B$248,A22) | C22: =COUNTIFS(Stories!$B$2:$B$248,A22,Stories!$H$2:$H$248,"Pass")+COUNTIFS(Stories!$B$2:$B$248,A22,Stories!$H$2:$H$248,"Pass (after fix)") | D22: =COUNTIFS(Stories!$B$2:$B$248,A22,Stories!$H$2:$H$248,"Fail")
A23: API: Security | B23: =COUNTIF(Stories!$B$2:$B$248,A23) | C23: =COUNTIFS(Stories!$B$2:$B$248,A23,Stories!$H$2:$H$248,"Pass")+COUNTIFS(Stories!$B$2:$B$248,A23,Stories!$H$2:$H$248,"Pass (after fix)") | D23: =COUNTIFS(Stories!$B$2:$B$248,A23,Stories!$H$2:$H$248,"Fail")
A24: API: Sentinel | B24: =COUNTIF(Stories!$B$2:$B$248,A24) | C24: =COUNTIFS(Stories!$B$2:$B$248,A24,Stories!$H$2:$H$248,"Pass")+COUNTIFS(Stories!$B$2:$B$248,A24,Stories!$H$2:$H$248,"Pass (after fix)") | D24: =COUNTIFS(Stories!$B$2:$B$248,A24,Stories!$H$2:$H$248,"Fail")
A25: API: Settings | B25: =COUNTIF(Stories!$B$2:$B$248,A25) | C25: =COUNTIFS(Stories!$B$2:$B$248,A25,Stories!$H$2:$H$248,"Pass")+COUNTIFS(Stories!$B$2:$B$248,A25,Stories!$H$2:$H$248,"Pass (after fix)") | D25: =COUNTIFS(Stories!$B$2:$B$248,A25,Stories!$H$2:$H$248,"Fail")
... A52: UI: Shell | B52: =COUNTIF(Stories!$B$2:$B$248,A52) | C52: =COUNTIFS(Stories!$B$2:$B$248,A52,Stories!$H$2:$H$248,"Pass")+COUNTIFS(Stories!$B$2:$B$248,A52,Stories!$H$2:$H$248,"Pass (after fix)") | D52: =COUNTIFS(Stories!$B$2:$B$248,A52,Stories!$H$2:$H$248,"Fail")

Sheet Legend
A1: Column | B1: Meaning
A2: Status | B2: Pick from list: Not tested / Pass / Fail / Fixed - retest / Pass (after fix) / Blocked (needs docker/LLM/Telegram) / Won't fix
A3: Test result | B3: What actually happened when the 'How to test' steps were run
A4: Error notes | B4: Concrete defect: request → observed vs expected, file:line if known
A5: Fix (commit / note) | B5: Commit hash or short note on the fix
A6: Retest result | B6: Outcome of re-running the story after the fix
A7: Editable cells | B7: Columns H–M on the Stories sheet are the tracking columns; A–G are derived from code by the inventory pass
